const x = 10

try{
    x = 11
}catch(err){
    console.log('erro!')
}